Traceback (most recent call last):
  File "/Users/petercharlton/anaconda3/lib/python3.8/site-packages/jupyter_cache/executors/utils.py", line 51, in single_nb_execution
    executenb(
  File "/Users/petercharlton/anaconda3/lib/python3.8/site-packages/nbclient/client.py", line 1112, in execute
    return NotebookClient(nb=nb, resources=resources, km=km, **kwargs).execute()
  File "/Users/petercharlton/anaconda3/lib/python3.8/site-packages/nbclient/util.py", line 74, in wrapped
    return just_run(coro(*args, **kwargs))
  File "/Users/petercharlton/anaconda3/lib/python3.8/site-packages/nbclient/util.py", line 53, in just_run
    return loop.run_until_complete(coro)
  File "/Users/petercharlton/anaconda3/lib/python3.8/asyncio/base_events.py", line 616, in run_until_complete
    return future.result()
  File "/Users/petercharlton/anaconda3/lib/python3.8/site-packages/nbclient/client.py", line 553, in async_execute
    await self.async_execute_cell(
  File "/Users/petercharlton/anaconda3/lib/python3.8/site-packages/nbclient/client.py", line 857, in async_execute_cell
    self._check_raise_for_error(cell, exec_reply)
  File "/Users/petercharlton/anaconda3/lib/python3.8/site-packages/nbclient/client.py", line 760, in _check_raise_for_error
    raise CellExecutionError.from_cell_and_msg(cell, exec_reply_content)
nbclient.exceptions.CellExecutionError: An error occurred while executing the following cell:
------------------
from matplotlib import pyplot as plt

fig, (ax1,ax2,ax3) = plt.subplots(3, 1,
                                  sharex = False,
                                  sharey = False,
                                  figsize = (8,8))
fig.suptitle('IBIs detection') 

t = np.arange(0, len(ppg_filt)/fs,1.0/fs)

ax1.plot(t, ppg_filt, color = 'black')
ax1.scatter(t[0] + ppg_ibis_d2max/fs,
            ppg_filt[ppg_ibis_d2max],
            color = 'orange',
            marker = 'o')
ax1.set_ylabel('PPG [V]')
ax1.set_title('D2Max')

ax2.plot(t, ppg_filt, color = 'black')
ax2.scatter(t[0] + ppg_ibis_upslopes/fs,
            ppg_filt[ppg_ibis_upslopes],
            color = 'orange',
            marker = 'o')
ax2.set_ylabel('PPG [V]')
ax2.set_title('Upslopes')

ax3.plot(t, ppg_filt, color = 'black')
ax3.scatter(t[0] + ppg_ibis_delineator/fs,
            ppg_filt[ppg_ibis_delineator],
            color = 'orange',
            marker = 'o')
ax3.set_xlabel('Time [s]')
ax3.set_ylabel('PPG [V]')
ax3.set_title('Delineator')
------------------

[0;31m---------------------------------------------------------------------------[0m
[0;31mNameError[0m                                 Traceback (most recent call last)
[0;32m<ipython-input-7-1890a203030f>[0m in [0;36m<module>[0;34m[0m
[1;32m      7[0m [0mfig[0m[0;34m.[0m[0msuptitle[0m[0;34m([0m[0;34m'IBIs detection'[0m[0;34m)[0m[0;34m[0m[0;34m[0m[0m
[1;32m      8[0m [0;34m[0m[0m
[0;32m----> 9[0;31m [0mt[0m [0;34m=[0m [0mnp[0m[0;34m.[0m[0marange[0m[0;34m([0m[0;36m0[0m[0;34m,[0m [0mlen[0m[0;34m([0m[0mppg_filt[0m[0;34m)[0m[0;34m/[0m[0mfs[0m[0;34m,[0m[0;36m1.0[0m[0;34m/[0m[0mfs[0m[0;34m)[0m[0;34m[0m[0;34m[0m[0m
[0m[1;32m     10[0m [0;34m[0m[0m
[1;32m     11[0m [0max1[0m[0;34m.[0m[0mplot[0m[0;34m([0m[0mt[0m[0;34m,[0m [0mppg_filt[0m[0;34m,[0m [0mcolor[0m [0;34m=[0m [0;34m'black'[0m[0;34m)[0m[0;34m[0m[0;34m[0m[0m

[0;31mNameError[0m: name 'np' is not defined
NameError: name 'np' is not defined

